<?xml version="1.0" ?>
<!-- =================================================================================== -->
<!-- |    This document was autogenerated by xacro from /home/prl/tycho_ws/src/tycho_description/robots/hebi_chopsticks.xacro | -->
<!-- |    EDITING THIS FILE BY HAND IS NOT RECOMMENDED                                 | -->
<!-- =================================================================================== -->
<!-- HEBI A-2085-06 6-DoF Robot Arm Kit -->
<robot name="hebi">
  <!-- Deprecated <xacro:property name="MOUNT_HEIGHT" value="0.010548" /> -->
  <!-- Mods: custom kinematic parameters -->
  <!-- This is a single xacro file you can include to get
  all of the HEBI components -->
  <!-- world -->
  <link name="world"/>
  <joint name="world_joint" type="fixed">
    <origin rpy="0 0 0" xyz="0 0 0"/>
    <parent link="world"/>
    <child link="base"/>
  </joint>
  <!-- just for visualization: base post -->
  <link name="base">
    <visual>
      <origin rpy="0 0 0" xyz="-.125 0 -.0254"/>
      <geometry>
        <box size="0.2 0.2 0.0508"/>
      </geometry>
      <material name="silver">
        <color rgba="0.6 0.6 0.6 1"/>
      </material>
    </visual>
    <collision>
      <origin rpy="0 0 0" xyz="-.125 0 -.0254"/>
      <geometry>
        <box size="0.25 0.5 0.0508"/>
      </geometry>
    </collision>
    <inertial>
      <origin rpy="0 0 0" xyz=".125 0 -.0254"/>
      <mass value="1.0"/>
      <inertia ixx="1.0" ixy="0.0" ixz="0.0" iyy="1.0" iyz="0.0" izz="1.0"/>
    </inertial>
  </link>
  <joint name="base_base" type="fixed">
    <parent link="base"/>
    <child link="HEBI/base/INPUT_INTERFACE"/>
    <origin rpy="0 0 0" xyz="0 0 0"/>
  </joint>
  <link name="HEBI/base/INPUT_INTERFACE">
    <visual>
      <origin rpy="0 0 0" xyz="0 0 0"/>
      <geometry>
        <mesh filename="package://tycho_description/meshes/X8.stl" scale="0.001 0.001 0.001"/>
      </geometry>
      <material name="red">
        <color rgba=".82 0.06 0.06 1"/>
      </material>
    </visual>
    <collision>
      <origin rpy="0 0 0" xyz="0 0 0"/>
      <geometry>
        <mesh filename="package://tycho_description/meshes/X8.stl" scale="0.001 0.001 0.001"/>
      </geometry>
    </collision>
    <inertial>
      <mass value="0.48"/>
      <origin rpy="0 0 0" xyz="-0.0145 -0.0031 0.0242"/>
      <inertia ixx="0.000246" ixy="0.0000444" ixz="0.0000266" iyy="0.000380" iyz="0.00000422" izz="0.000463"/>
    </inertial>
  </link>
  <joint name="HEBI/base/X8_9" type="revolute">
    <parent link="HEBI/base/INPUT_INTERFACE"/>
    <child link="shoulder_bracket/INPUT_INTERFACE"/>
    <origin rpy="0 0 0" xyz="0 0 0.0451"/>
    <!-- IDK why HebiRobotics/tycho_description changed 0.0451 to 0.045 whereas the previous official release was 0.0451. For now we kept the old number. -->
    <axis xyz="0 0 1"/>
    <limit effort="20" lower="-6.283185307179586" upper="3.141592653589793" velocity="3.142"/>
    <dynamics damping="0.5" friction="0.5"/>
  </joint>
  <link name="shoulder_bracket/INPUT_INTERFACE">
    <visual>
      <origin rpy="1.5707963267948966 0 1.5707963267948966" xyz="0 0 0.005"/>
      <geometry>
        <mesh filename="package://tycho_description/meshes/PM-2149-01.stl" scale="0.001 0.001 0.001"/>
      </geometry>
      <material name="black">
        <color rgba="0.1 0.1 0.1 1"/>
      </material>
    </visual>
    <visual>
      <origin rpy="1.5707963267948966 0 0" xyz="0 -.03 .04"/>
      <geometry>
        <mesh filename="package://tycho_description/meshes/PM-2150-01R.stl" scale="0.001 0.001 0.001"/>
      </geometry>
      <material name="black">
        <color rgba="0.1 0.1 0.1 1"/>
      </material>
    </visual>
    <collision>
      <origin rpy="1.5707963267948966 0 1.5707963267948966" xyz="0 0 0.005"/>
      <geometry>
        <mesh filename="package://tycho_description/meshes/PM-2149-01.stl" scale="0.001 0.001 0.001"/>
      </geometry>
    </collision>
    <collision>
      <origin rpy="1.5707963267948966 0 0" xyz="0 -.03 .04"/>
      <geometry>
        <mesh filename="package://tycho_description/meshes/PM-2150-01R.stl" scale="0.001 0.001 0.001"/>
      </geometry>
    </collision>
    <!-- NOTE: inertia is just modelled as small sphere, and could be improved. -->
    <inertial>
      <origin rpy="0 0 0" xyz="0 -0.01875 .0275"/>
      <mass value="0.215"/>
      <inertia ixx="0.00030960000000000004" ixy="0.0" ixz="0.0" iyy="0.00030960000000000004" iyz="0.0" izz="0.00030960000000000004"/>
    </inertial>
  </link>
  <joint name="shoulder_bracket/OUTPUT_INTERFACE" type="fixed">
    <parent link="shoulder_bracket/INPUT_INTERFACE"/>
    <child link="HEBI/shoulder/INPUT_INTERFACE"/>
    <!-- Official Original Version
    <xacro:if value="${bracket_type.endswith('RightOutside')}">
      <origin xyz="0 -.0375 .055" rpy="${pi/2} 0 0"/>
    </xacro:if>
    <xacro:if value="${bracket_type.endswith('RightInside')}">
      <origin xyz="0 .0225 .055" rpy="${pi/2} 0 0"/>
    </xacro:if>
    <xacro:if value="${bracket_type.endswith('LeftOutside')}">
      <origin xyz="0 .0375 .055" rpy="${-pi/2} 0 0"/>
    </xacro:if>
    <xacro:if value="${bracket_type.endswith('LeftInside')}">
      <origin xyz="0 -.0225 .055" rpy="${-pi/2} 0 0"/>
    </xacro:if>
    <xacro:if value="${bracket_type.endswith('Left')}">
      <origin xyz="0 .043 .04" rpy="${-pi/2} 0 0"/>
    </xacro:if>
    <xacro:if value="${bracket_type.endswith('Right')}">
      <origin xyz="0 -.043 .04" rpy="${pi/2} 0 0"/>
    </xacro:if> -->
    <origin rpy="1.570789735098025 0 1.97751938338511e-06" xyz="0.0 -0.03722539360652703 0.056366367059580716"/>
  </joint>
  <link name="HEBI/shoulder/INPUT_INTERFACE">
    <visual>
      <origin rpy="0 0 0" xyz="0 0 0"/>
      <geometry>
        <mesh filename="package://tycho_description/meshes/X8.stl" scale="0.001 0.001 0.001"/>
      </geometry>
      <material name="red">
        <color rgba=".82 0.06 0.06 1"/>
      </material>
    </visual>
    <collision>
      <origin rpy="0 0 0" xyz="0 0 0"/>
      <geometry>
        <mesh filename="package://tycho_description/meshes/X8.stl" scale="0.001 0.001 0.001"/>
      </geometry>
    </collision>
    <inertial>
      <mass value="0.5"/>
      <origin rpy="0 0 0" xyz="-0.0145 -0.0031 0.0242"/>
      <inertia ixx="0.000246" ixy="0.0000444" ixz="0.0000266" iyy="0.000380" iyz="0.00000422" izz="0.000463"/>
    </inertial>
  </link>
  <joint name="HEBI/shoulder/X8_16" type="revolute">
    <parent link="HEBI/shoulder/INPUT_INTERFACE"/>
    <child link="shoulder_elbow/INPUT_INTERFACE"/>
    <origin rpy="0 0 0" xyz="0 0 0.0451"/>
    <!-- IDK why HebiRobotics/tycho_description changed 0.0451 to 0.045 whereas the previous official release was 0.0451. For now we kept the old number. -->
    <axis xyz="0 0 1"/>
    <limit effort="38" lower="-0.5" upper="3.141592653589793" velocity="1.571"/>
    <dynamics damping="0.5" friction="0.5"/>
  </joint>
  <link name="shoulder_elbow/INPUT_INTERFACE">
    <!-- Input Cap -->
    <visual>
      <origin rpy="0 0 0" xyz="0 0 0"/>
      <geometry>
        <mesh filename="package://tycho_description/meshes/A-2038-02.stl"/>
      </geometry>
      <material name="black">
        <color rgba="0.1 0.1 0.1 1"/>
      </material>
    </visual>
    <collision>
      <origin rpy="0 0 0" xyz="0 0 0"/>
      <geometry>
        <mesh filename="package://tycho_description/meshes/A-2038-02.stl"/>
      </geometry>
    </collision>
    <!-- Link Pipe -->
    <visual>
      <origin rpy="0 1.57075 0" xyz="0.16314533157404612 0 0.02"/>
      <geometry>
        <cylinder length="0.30089066314809226" radius=".016"/>
      </geometry>
      <material name="black">
        <color rgba="0.1 0.1 0.1 1"/>
      </material>
    </visual>
    <collision>
      <origin rpy="0 1.57075 0" xyz="0.16314533157404612 0 0.02"/>
      <geometry>
        <cylinder length="0.30089066314809226" radius=".016"/>
      </geometry>
    </collision>
    <!-- Output Cap -->
    <visual>
      <origin rpy="-3.1415966337120738 0 0" xyz="0.32629066314809224 7.96024456102324e-08 1.584132824916651e-13"/>
      <geometry>
        <mesh filename="package://tycho_description/meshes/A-2039-02.stl"/>
      </geometry>
      <material name="black">
        <color rgba="0.1 0.1 0.1 1"/>
      </material>
    </visual>
    <collision>
      <origin rpy="-3.1415966337120738 0 0" xyz="0.32629066314809224 7.96024456102324e-08 1.584132824916651e-13"/>
      <geometry>
        <mesh filename="package://tycho_description/meshes/A-2039-02.stl"/>
      </geometry>
    </collision>
    <!-- Approximate inertia as thin rod about x axis -->
    <inertial>
      <origin rpy="0 0 0" xyz="0.16314533157404612 0 0.02"/>
      <mass value="0.4025162652592369"/>
      <inertia ixx="0.0" ixy="0.0" ixz="0.0" iyy="0.0035711778688104563" iyz="0.0" izz="0.0035711778688104563"/>
    </inertial>
  </link>
  <!-- Official Version
    <joint name="${name}/OUTPUT_JOINT" type="fixed">
      <parent link="${name}/INPUT_INTERFACE"/>
      <child link="${child}/INPUT_INTERFACE"/>
      <origin xyz="${extension} ${-sin(twist) * edge_to_center} ${edge_to_center * (1 + cos(twist))}" rpy="${twist} 0 0"/>
    </joint>
    -->
  <!-- Mods: Use custom kinematic parameters -->
  <joint name="shoulder_elbow/OUTPUT_JOINT" type="fixed">
    <parent link="shoulder_elbow/INPUT_INTERFACE"/>
    <child link="HEBI/elbow/INPUT_INTERFACE"/>
    <!-- xyz=a3(extension),0,0.0451-d3, rpy=alpha3,0,0 -->
    <origin rpy="3.1415966337120738 0 0" xyz="0.32629066314809224 0 -0.000427853003693017"/>
  </joint>
  <link name="HEBI/elbow/INPUT_INTERFACE">
    <visual>
      <origin rpy="0 0 0" xyz="0 0 0"/>
      <geometry>
        <mesh filename="package://tycho_description/meshes/X8.stl" scale="0.001 0.001 0.001"/>
      </geometry>
      <material name="red">
        <color rgba=".82 0.06 0.06 1"/>
      </material>
    </visual>
    <collision>
      <origin rpy="0 0 0" xyz="0 0 0"/>
      <geometry>
        <mesh filename="package://tycho_description/meshes/X8.stl" scale="0.001 0.001 0.001"/>
      </geometry>
    </collision>
    <inertial>
      <mass value="0.48"/>
      <origin rpy="0 0 0" xyz="-0.0145 -0.0031 0.0242"/>
      <inertia ixx="0.000246" ixy="0.0000444" ixz="0.0000266" iyy="0.000380" iyz="0.00000422" izz="0.000463"/>
    </inertial>
  </link>
  <joint name="HEBI/elbow/X8_9" type="revolute">
    <parent link="HEBI/elbow/INPUT_INTERFACE"/>
    <child link="elbow_wrist1/INPUT_INTERFACE"/>
    <origin rpy="0 0 0" xyz="0 0 0.0451"/>
    <!-- IDK why HebiRobotics/tycho_description changed 0.0451 to 0.045 whereas the previous official release was 0.0451. For now we kept the old number. -->
    <axis xyz="0 0 1"/>
    <limit effort="20" lower="-3" upper="3" velocity="3.142"/>
    <dynamics damping="0.5" friction="0.5"/>
  </joint>
  <link name="elbow_wrist1/INPUT_INTERFACE">
    <!-- Input Cap -->
    <visual>
      <origin rpy="0 0 0" xyz="0 0 0"/>
      <geometry>
        <mesh filename="package://tycho_description/meshes/A-2038-02.stl"/>
      </geometry>
      <material name="black">
        <color rgba="0.1 0.1 0.1 1"/>
      </material>
    </visual>
    <collision>
      <origin rpy="0 0 0" xyz="0 0 0"/>
      <geometry>
        <mesh filename="package://tycho_description/meshes/A-2038-02.stl"/>
      </geometry>
    </collision>
    <!-- Link Pipe -->
    <visual>
      <origin rpy="0 1.57075 0" xyz="0.16365985768373773 0 0.02"/>
      <geometry>
        <cylinder length="0.30191971536747547" radius=".016"/>
      </geometry>
      <material name="black">
        <color rgba="0.1 0.1 0.1 1"/>
      </material>
    </visual>
    <collision>
      <origin rpy="0 1.57075 0" xyz="0.16365985768373773 0 0.02"/>
      <geometry>
        <cylinder length="0.30191971536747547" radius=".016"/>
      </geometry>
    </collision>
    <!-- Output Cap -->
    <visual>
      <origin rpy="-3.1362727199993574 0 0" xyz="0.32731971536747545 -0.00010639816993232858 2.830162665778957e-07"/>
      <geometry>
        <mesh filename="package://tycho_description/meshes/A-2039-02.stl"/>
      </geometry>
      <material name="black">
        <color rgba="0.1 0.1 0.1 1"/>
      </material>
    </visual>
    <collision>
      <origin rpy="-3.1362727199993574 0 0" xyz="0.32731971536747545 -0.00010639816993232858 2.830162665778957e-07"/>
      <geometry>
        <mesh filename="package://tycho_description/meshes/A-2039-02.stl"/>
      </geometry>
    </collision>
    <!-- Approximate inertia as thin rod about x axis -->
    <inertial>
      <origin rpy="0 0 0" xyz="0.16365985768373773 0 0.02"/>
      <mass value="0.40292788614699016"/>
      <inertia ixx="0.0" ixy="0.0" ixz="0.0" iyy="0.0035974139056149826" iyz="0.0" izz="0.0035974139056149826"/>
    </inertial>
  </link>
  <!-- Official Version
    <joint name="${name}/OUTPUT_JOINT" type="fixed">
      <parent link="${name}/INPUT_INTERFACE"/>
      <child link="${child}/INPUT_INTERFACE"/>
      <origin xyz="${extension} ${-sin(twist) * edge_to_center} ${edge_to_center * (1 + cos(twist))}" rpy="${twist} 0 0"/>
    </joint>
    -->
  <!-- Mods: Use custom kinematic parameters -->
  <joint name="elbow_wrist1/OUTPUT_JOINT" type="fixed">
    <parent link="elbow_wrist1/INPUT_INTERFACE"/>
    <child link="HEBI/wrist1/INPUT_INTERFACE"/>
    <!-- xyz=a4(extension),0,0, rpy=alpha4,0,0 -->
    <origin rpy="3.1362727199993574 0 0" xyz="0.32731971536747545 0 0"/>
  </joint>
  <link name="HEBI/wrist1/INPUT_INTERFACE">
    <visual>
      <origin rpy="0 0 0" xyz="0 0 0"/>
      <geometry>
        <mesh filename="package://tycho_description/meshes/X5.stl" scale="0.001 0.001 0.001"/>
      </geometry>
      <material name="red">
        <color rgba=".82 0.06 0.06 1"/>
      </material>
    </visual>
    <collision>
      <origin rpy="0 0 0" xyz="0 0 0"/>
      <geometry>
        <mesh filename="package://tycho_description/meshes/X5.stl" scale="0.001 0.001 0.001"/>
      </geometry>
    </collision>
    <inertial>
      <mass value="0.315"/>
      <origin rpy="0 0 0" xyz="-0.0142 -0.0031 0.0165"/>
      <inertia ixx="0.00015" ixy="0.0000341" ixz="0.0000118" iyy="0.000255" iyz="0.00000229" izz="0.000350"/>
    </inertial>
  </link>
  <joint name="HEBI/wrist1/X5_1" type="revolute">
    <parent link="HEBI/wrist1/INPUT_INTERFACE"/>
    <child link="wrist1_wrist2/INPUT_INTERFACE"/>
    <origin rpy="0 0 0" xyz="0 0 0.0313"/>
    <!-- IDK why HebiRobotics/tycho_description changed 0.0313 to 0.031 whereas the previous official release was 0.0313. For now we kept the old number. -->
    <axis xyz="0 0 1"/>
    <limit effort="2.5" lower="-6.283185307179586" upper="6.283185307179586" velocity="9.425"/>
    <dynamics damping="0.1" friction="0.1"/>
  </joint>
  <link name="wrist1_wrist2/INPUT_INTERFACE">
    <visual>
      <origin rpy="1.5707963267948966 0 -1.5707963267948966" xyz="0 0 0"/>
      <geometry>
        <mesh filename="package://tycho_description/meshes/PM-2132-01R.stl" scale="0.001 0.001 0.001"/>
      </geometry>
      <material name="black">
        <color rgba="0.1 0.1 0.1 1"/>
      </material>
    </visual>
    <collision>
      <origin rpy="1.5707963267948966 0 -1.5707963267948966" xyz="0 0 0"/>
      <geometry>
        <mesh filename="package://tycho_description/meshes/PM-2132-01R.stl" scale="0.001 0.001 0.001"/>
      </geometry>
    </collision>
    <!-- NOTE: inertia is just modelled as small sphere, and could be improved. -->
    <inertial>
      <origin rpy="0 0 0" xyz="0 -.0215 .02"/>
      <mass value="0.1"/>
      <inertia ixx="0.000144" ixy="0.0" ixz="0.0" iyy="0.000144" iyz="0.0" izz="0.000144"/>
    </inertial>
  </link>
  <joint name="wrist1_wrist2/OUTPUT_INTERFACE" type="fixed">
    <parent link="wrist1_wrist2/INPUT_INTERFACE"/>
    <child link="HEBI/wrist2/INPUT_INTERFACE"/>
    <!-- Official Original Version
    <xacro:if value="${bracket_type.endswith('RightOutside')}">
      <origin xyz="0 -.0375 .055" rpy="${pi/2} 0 0"/>
    </xacro:if>
    <xacro:if value="${bracket_type.endswith('RightInside')}">
      <origin xyz="0 .0225 .055" rpy="${pi/2} 0 0"/>
    </xacro:if>
    <xacro:if value="${bracket_type.endswith('LeftOutside')}">
      <origin xyz="0 .0375 .055" rpy="${-pi/2} 0 0"/>
    </xacro:if>
    <xacro:if value="${bracket_type.endswith('LeftInside')}">
      <origin xyz="0 -.0225 .055" rpy="${-pi/2} 0 0"/>
    </xacro:if>
    <xacro:if value="${bracket_type.endswith('Left')}">
      <origin xyz="0 .043 .04" rpy="${-pi/2} 0 0"/>
    </xacro:if>
    <xacro:if value="${bracket_type.endswith('Right')}">
      <origin xyz="0 -.043 .04" rpy="${pi/2} 0 0"/>
    </xacro:if> -->
    <origin rpy="1.5707977550582384 0 0" xyz="0.0 -.043 0.03970628183517872"/>
  </joint>
  <link name="HEBI/wrist2/INPUT_INTERFACE">
    <visual>
      <origin rpy="0 0 0" xyz="0 0 0"/>
      <geometry>
        <mesh filename="package://tycho_description/meshes/X5.stl" scale="0.001 0.001 0.001"/>
      </geometry>
      <material name="red">
        <color rgba=".82 0.06 0.06 1"/>
      </material>
    </visual>
    <collision>
      <origin rpy="0 0 0" xyz="0 0 0"/>
      <geometry>
        <mesh filename="package://tycho_description/meshes/X5.stl" scale="0.001 0.001 0.001"/>
      </geometry>
    </collision>
    <inertial>
      <mass value="0.315"/>
      <origin rpy="0 0 0" xyz="-0.0142 -0.0031 0.0165"/>
      <inertia ixx="0.00015" ixy="0.0000341" ixz="0.0000118" iyy="0.000255" iyz="0.00000229" izz="0.000350"/>
    </inertial>
  </link>
  <joint name="HEBI/wrist2/X5_1" type="revolute">
    <parent link="HEBI/wrist2/INPUT_INTERFACE"/>
    <child link="wrist2_wrist3/INPUT_INTERFACE"/>
    <origin rpy="0 0 0" xyz="0 0 0.0313"/>
    <!-- IDK why HebiRobotics/tycho_description changed 0.0313 to 0.031 whereas the previous official release was 0.0313. For now we kept the old number. -->
    <axis xyz="0 0 1"/>
    <limit effort="2.5" lower="-4.71238898038469" upper="4.71238898038469" velocity="9.425"/>
    <dynamics damping="0.1" friction="0.1"/>
  </joint>
  <link name="wrist2_wrist3/INPUT_INTERFACE">
    <visual>
      <origin rpy="1.5707963267948966 0 -1.5707963267948966" xyz="0 0 0"/>
      <geometry>
        <mesh filename="package://tycho_description/meshes/PM-2132-01R.stl" scale="0.001 0.001 0.001"/>
      </geometry>
      <material name="black">
        <color rgba="0.1 0.1 0.1 1"/>
      </material>
    </visual>
    <collision>
      <origin rpy="1.5707963267948966 0 -1.5707963267948966" xyz="0 0 0"/>
      <geometry>
        <mesh filename="package://tycho_description/meshes/PM-2132-01R.stl" scale="0.001 0.001 0.001"/>
      </geometry>
    </collision>
    <!-- NOTE: inertia is just modelled as small sphere, and could be improved. -->
    <inertial>
      <origin rpy="0 0 0" xyz="0 -.0215 .02"/>
      <mass value="0.1"/>
      <inertia ixx="0.000144" ixy="0.0" ixz="0.0" iyy="0.000144" iyz="0.0" izz="0.000144"/>
    </inertial>
  </link>
  <joint name="wrist2_wrist3/OUTPUT_INTERFACE" type="fixed">
    <parent link="wrist2_wrist3/INPUT_INTERFACE"/>
    <child link="HEBI/wrist3/INPUT_INTERFACE"/>
    <!-- Official Original Version
    <xacro:if value="${bracket_type.endswith('RightOutside')}">
      <origin xyz="0 -.0375 .055" rpy="${pi/2} 0 0"/>
    </xacro:if>
    <xacro:if value="${bracket_type.endswith('RightInside')}">
      <origin xyz="0 .0225 .055" rpy="${pi/2} 0 0"/>
    </xacro:if>
    <xacro:if value="${bracket_type.endswith('LeftOutside')}">
      <origin xyz="0 .0375 .055" rpy="${-pi/2} 0 0"/>
    </xacro:if>
    <xacro:if value="${bracket_type.endswith('LeftInside')}">
      <origin xyz="0 -.0225 .055" rpy="${-pi/2} 0 0"/>
    </xacro:if>
    <xacro:if value="${bracket_type.endswith('Left')}">
      <origin xyz="0 .043 .04" rpy="${-pi/2} 0 0"/>
    </xacro:if>
    <xacro:if value="${bracket_type.endswith('Right')}">
      <origin xyz="0 -.043 .04" rpy="${pi/2} 0 0"/>
    </xacro:if> -->
    <origin rpy="1.5707990908361669 0 0" xyz="-0.0 -0.04243140497245554 0.03972510192401031 "/>
  </joint>
  <link name="HEBI/wrist3/INPUT_INTERFACE">
    <visual>
      <origin rpy="0 0 0" xyz="0 0 0"/>
      <geometry>
        <mesh filename="package://tycho_description/meshes/X5.stl" scale="0.001 0.001 0.001"/>
      </geometry>
      <material name="red">
        <color rgba=".82 0.06 0.06 1"/>
      </material>
    </visual>
    <collision>
      <origin rpy="0 0 0" xyz="0 0 0"/>
      <geometry>
        <mesh filename="package://tycho_description/meshes/X5.stl" scale="0.001 0.001 0.001"/>
      </geometry>
    </collision>
    <inertial>
      <mass value="0.315"/>
      <origin rpy="0 0 0" xyz="-0.0142 -0.0031 0.0165"/>
      <inertia ixx="0.00015" ixy="0.0000341" ixz="0.0000118" iyy="0.000255" iyz="0.00000229" izz="0.000350"/>
    </inertial>
  </link>
  <joint name="HEBI/wrist3/X5_1" type="continuous">
    <parent link="HEBI/wrist3/INPUT_INTERFACE"/>
    <child link="wrist3_chopstick/INPUT_INTERFACE"/>
    <origin rpy="0 0 0" xyz="0 0 0.0313"/>
    <!-- IDK why HebiRobotics/tycho_description changed 0.0313 to 0.031 whereas the previous official release was 0.0313. For now we kept the old number. -->
    <axis xyz="0 0 1"/>
    <limit effort="2.5" velocity="9.425"/>
    <dynamics damping="0.1" friction="0.1"/>
  </joint>
  <link name="wrist3_chopstick/INPUT_INTERFACE">
    <visual>
      <origin rpy="1.5707963267948966 0 1.5707963267948966" xyz="0 0 0"/>
      <geometry>
        <mesh filename="package://tycho_description/meshes/PM-2132-01L.stl" scale="0.001 0.001 0.001"/>
      </geometry>
      <material name="beige">
        <color rgba="0.96 0.945 0.871 1"/>
      </material>
    </visual>
    <collision>
      <origin rpy="1.5707963267948966 0 1.5707963267948966" xyz="0 0 0"/>
      <geometry>
        <mesh filename="package://tycho_description/meshes/PM-2132-01L.stl" scale="0.001 0.001 0.001"/>
      </geometry>
    </collision>
    <!-- NOTE: inertia is just modelled as small sphere, and could be improved. -->
    <inertial>
      <origin rpy="0 0 0" xyz="0 .0215 .02"/>
      <mass value="0.1"/>
      <inertia ixx="0.000144" ixy="0.0" ixz="0.0" iyy="0.000144" iyz="0.0" izz="0.000144"/>
    </inertial>
  </link>
  <joint name="wrist3_chopstick/OUTPUT_INTERFACE" type="fixed">
    <parent link="wrist3_chopstick/INPUT_INTERFACE"/>
    <child link="HEBI/chopstick_actuator/INPUT_INTERFACE"/>
    <!-- Official Original Version
    <xacro:if value="${bracket_type.endswith('RightOutside')}">
      <origin xyz="0 -.0375 .055" rpy="${pi/2} 0 0"/>
    </xacro:if>
    <xacro:if value="${bracket_type.endswith('RightInside')}">
      <origin xyz="0 .0225 .055" rpy="${pi/2} 0 0"/>
    </xacro:if>
    <xacro:if value="${bracket_type.endswith('LeftOutside')}">
      <origin xyz="0 .0375 .055" rpy="${-pi/2} 0 0"/>
    </xacro:if>
    <xacro:if value="${bracket_type.endswith('LeftInside')}">
      <origin xyz="0 -.0225 .055" rpy="${-pi/2} 0 0"/>
    </xacro:if>
    <xacro:if value="${bracket_type.endswith('Left')}">
      <origin xyz="0 .043 .04" rpy="${-pi/2} 0 0"/>
    </xacro:if>
    <xacro:if value="${bracket_type.endswith('Right')}">
      <origin xyz="0 -.043 .04" rpy="${pi/2} 0 0"/>
    </xacro:if> -->
    <origin rpy="-1.5707963267948966 0 0" xyz="0 .043 .04"/>
    <!-- The number follows bracket_type.endswith('Left') -->
  </joint>
  <link name="HEBI/chopstick_actuator/INPUT_INTERFACE">
    <visual>
      <origin rpy="0 0 0" xyz="0 0 0"/>
      <geometry>
        <mesh filename="package://tycho_description/meshes/X5.stl" scale="0.001 0.001 0.001"/>
      </geometry>
      <material name="red">
        <color rgba=".82 0.06 0.06 1"/>
      </material>
    </visual>
    <collision>
      <origin rpy="0 0 0" xyz="0 0 0"/>
      <geometry>
        <mesh filename="package://tycho_description/meshes/X5.stl" scale="0.001 0.001 0.001"/>
      </geometry>
    </collision>
    <inertial>
      <mass value="0.315"/>
      <origin rpy="0 0 0" xyz="-0.0142 -0.0031 0.0165"/>
      <inertia ixx="0.00015" ixy="0.0000341" ixz="0.0000118" iyy="0.000255" iyz="0.00000229" izz="0.000350"/>
    </inertial>
  </link>
  <joint name="HEBI/chopstick_actuator/X5_1" type="continuous">
    <parent link="HEBI/chopstick_actuator/INPUT_INTERFACE"/>
    <child link="end_effector/INPUT_INTERFACE"/>
    <origin rpy="0 0 0" xyz="0 0 0.0313"/>
    <!-- IDK why HebiRobotics/tycho_description changed 0.0313 to 0.031 whereas the previous official release was 0.0313. For now we kept the old number. -->
    <axis xyz="0 0 1"/>
    <limit effort="2.5" velocity="9.425"/>
    <dynamics damping="0.1" friction="0.1"/>
  </joint>
  <!-- Chopstick -->
  <link name="HEBI/static_mount/chopstick_link">
    <visual>
      <origin rpy="0 0 0" xyz="0 0 0"/>
      <geometry>
        <mesh filename="package://tycho_description/meshes/chopstick.stl"/>
      </geometry>
      <material name="beige">
        <color rgba="0.96 0.945 0.871 1"/>
      </material>
    </visual>
    <collision>
      <origin rpy="0 0 0" xyz="0 0 0"/>
      <geometry>
        <mesh filename="package://tycho_description/meshes/chopstick_collision.stl"/>
      </geometry>
    </collision>
    <inertial>
      <origin rpy="0 0 0" xyz="0 0 0"/>
      <mass value="0.0075"/>
      <inertia ixx="0.00000003" ixy="0.0" ixz="0.0" iyy="0.00000003" iyz="0.0" izz="0.00000003"/>
    </inertial>
  </link>
  <!-- Tip Link ? IDK why there is a separate link ?  -->
  <link name="HEBI/static_mount/chopstick_tip_link">
    <inertial>
      <origin rpy="0 0 0" xyz="0 0 0"/>
      <mass value="0.001"/>
      <inertia ixx="0.00000003" ixy="0.0" ixz="0.0" iyy="0.00000003" iyz="0.0" izz="0.00000003"/>
    </inertial>
  </link>
  <joint name="HEBI/static_mount/chopstick_to_tip_joint" type="fixed">
    <origin rpy="0 0 0" xyz="0.115 0 0"/>
    <parent link="HEBI/static_mount/chopstick_link"/>
    <child link="HEBI/static_mount/chopstick_tip_link"/>
  </joint>
  <link name="HEBI/static_mount/back_mount_link">
    <visual>
      <origin rpy="0 0 0" xyz="0 0 0"/>
      <geometry>
        <mesh filename="package://tycho_description/meshes/chopstick_mount_m3.stl"/>
      </geometry>
      <material name="black">
        <color rgba="0.1 0.1 0.1 1"/>
      </material>
    </visual>
    <collision>
      <origin rpy="0 0 0" xyz="0 0 0"/>
      <geometry>
        <mesh filename="package://tycho_description/meshes/chopstick_mount_m3_collision.stl"/>
      </geometry>
    </collision>
    <inertial>
      <origin rpy="0 0 0" xyz="0 0 0"/>
      <mass value="0.00125"/>
      <inertia ixx="0.00000003" ixy="0.0" ixz="0.0" iyy="0.00000003" iyz="0.0" izz="0.00000003"/>
    </inertial>
  </link>
  <joint name="HEBI/static_mount/chopstick_to_back_mount_joint" type="fixed">
    <origin rpy="0 0 0" xyz="-0.053000000000000005 -0.0045 0"/>
    <parent link="HEBI/static_mount/chopstick_link"/>
    <child link="HEBI/static_mount/back_mount_link"/>
  </joint>
  <link name="HEBI/static_mount/front_mount_link">
    <visual>
      <origin rpy="0 0 0" xyz="0 0 0"/>
      <geometry>
        <mesh filename="package://tycho_description/meshes/chopstick_mount_m3.stl"/>
      </geometry>
      <material name="black">
        <color rgba="0.1 0.1 0.1 1"/>
      </material>
    </visual>
    <collision>
      <origin rpy="0 0 0" xyz="0 0 0"/>
      <geometry>
        <mesh filename="package://tycho_description/meshes/chopstick_mount_m3_collision.stl"/>
      </geometry>
    </collision>
    <inertial>
      <origin rpy="0 0 0" xyz="0 0 0"/>
      <mass value="0.00125"/>
      <inertia ixx="0.00000003" ixy="0.0" ixz="0.0" iyy="0.00000003" iyz="0.0" izz="0.00000003"/>
    </inertial>
  </link>
  <joint name="HEBI/static_mount/back_mount_to_front_mount_joint" type="fixed">
    <origin rpy="0 0 0" xyz="0.065 0 0"/>
    <parent link="HEBI/static_mount/back_mount_link"/>
    <child link="HEBI/static_mount/front_mount_link"/>
  </joint>
  <link name="HEBI/rotary_mount/chopstick_link">
    <visual>
      <origin rpy="0 0 0" xyz="0 0 0"/>
      <geometry>
        <mesh filename="package://tycho_description/meshes/chopstick.stl"/>
      </geometry>
      <material name="beige">
        <color rgba="0.96 0.945 0.871 1"/>
      </material>
    </visual>
    <collision>
      <origin rpy="0 0 0" xyz="0 0 0"/>
      <geometry>
        <mesh filename="package://tycho_description/meshes/chopstick_collision.stl"/>
      </geometry>
    </collision>
    <inertial>
      <origin rpy="0 0 0" xyz="0 0 0"/>
      <mass value="0.0075"/>
      <inertia ixx="0.00000003" ixy="0.0" ixz="0.0" iyy="0.00000003" iyz="0.0" izz="0.00000003"/>
    </inertial>
  </link>
  <link name="HEBI/rotary_mount/chopstick_tip_link">
    <inertial>
      <origin rpy="0 0 0" xyz="0 0 0"/>
      <mass value="0.001"/>
      <inertia ixx="0.00000003" ixy="0.0" ixz="0.0" iyy="0.00000003" iyz="0.0" izz="0.00000003"/>
    </inertial>
  </link>
  <joint name="HEBI/rotary_mount/chopstick_to_tip_joint" type="fixed">
    <origin rpy="0 0 0" xyz="0.115 0 0"/>
    <parent link="HEBI/rotary_mount/chopstick_link"/>
    <child link="HEBI/rotary_mount/chopstick_tip_link"/>
  </joint>
  <link name="HEBI/rotary_mount/back_mount_link">
    <visual>
      <origin rpy="0 0 0" xyz="0 0 0"/>
      <geometry>
        <mesh filename="package://tycho_description/meshes/chopstick_mount_m5.stl"/>
      </geometry>
      <material name="black">
        <color rgba="0.1 0.1 0.1 1"/>
      </material>
    </visual>
    <collision>
      <origin rpy="0 0 0" xyz="0 0 0"/>
      <geometry>
        <mesh filename="package://tycho_description/meshes/chopstick_mount_m5_collision.stl"/>
      </geometry>
    </collision>
    <inertial>
      <origin rpy="0 0 0" xyz="0 0 0"/>
      <mass value="0.0015"/>
      <inertia ixx="0.00000003" ixy="0.0" ixz="0.0" iyy="0.00000003" iyz="0.0" izz="0.00000003"/>
    </inertial>
  </link>
  <joint name="HEBI/rotary_mount/chopstick_to_back_mount_joint" type="fixed">
    <origin rpy="0 0 0" xyz="-0.023000000000000007 -0.0045 0"/>
    <parent link="HEBI/rotary_mount/chopstick_link"/>
    <child link="HEBI/rotary_mount/back_mount_link"/>
  </joint>
  <link name="HEBI/rotary_mount/front_mount_link">
    <visual>
      <origin rpy="0 0 0" xyz="0 0 0"/>
      <geometry>
        <mesh filename="package://tycho_description/meshes/chopstick_mount_m5.stl"/>
      </geometry>
      <material name="black">
        <color rgba="0.1 0.1 0.1 1"/>
      </material>
    </visual>
    <collision>
      <origin rpy="0 0 0" xyz="0 0 0"/>
      <geometry>
        <mesh filename="package://tycho_description/meshes/chopstick_mount_m5_collision.stl"/>
      </geometry>
    </collision>
    <inertial>
      <origin rpy="0 0 0" xyz="0 0 0"/>
      <mass value="0.0015"/>
      <inertia ixx="0.00000003" ixy="0.0" ixz="0.0" iyy="0.00000003" iyz="0.0" izz="0.00000003"/>
    </inertial>
  </link>
  <joint name="HEBI/rotary_mount/back_mount_to_front_mount_joint" type="fixed">
    <origin rpy="0 0 0" xyz="0.03536 0 0"/>
    <parent link="HEBI/rotary_mount/back_mount_link"/>
    <child link="HEBI/rotary_mount/front_mount_link"/>
  </joint>
  <joint name="HEBI/static_mount_joint" type="fixed">
    <origin rpy="0 0 0" xyz="5.09387735542384e-06 -0.024431404997778062 0.03654729440645285"/>
    <!-- <origin xyz="0.0015 -0.02325 ${MOUNT_HEIGHT/2.0+0.03075}" rpy="0 0 0" /> -->
    <parent link="HEBI/chopstick_actuator/INPUT_INTERFACE"/>
    <child link="HEBI/static_mount/chopstick_link"/>
  </joint>
  <!-- end link -->
  <link name="end_effector/INPUT_INTERFACE">
  </link>
  <joint name="HEBI/rotary_mount_joint" type="fixed">
    <!--origin xyz="0.001 0.0048 ${MOUNT_HEIGHT/2.0}" rpy=" 0 0 0.3798" /-->
    <!-- z=_y-0.043-0.0313 -->
    <!--<origin xyz="0.0095 0.0048 ${0.08030005510000000346-0.043-0.0313}" rpy=" 0 0 0.42" />-->
    <origin rpy=" 0 0 0.42" xyz="0.0095 0.0048 0.00524729440645285"/>
    <parent link="end_effector/INPUT_INTERFACE"/>
    <child link="HEBI/rotary_mount/chopstick_link"/>
  </joint>
  <gazebo reference="base">
    <selfCollide>true</selfCollide>
  </gazebo>
  <gazebo>
    <plugin filename="libhebiros_gazebo_plugin.so" name="hebiros_gazebo_plugin">
    </plugin>
  </gazebo>
</robot>
